{"errorMessage":"Lambda process returned with error. Result: {\"errorType\":\"AttributeError\",\"errorMessage\":\"'dict' object has no attribute 'replace'\",\"stackTrace\":[\"  File \\\"/var/task/lambda.py\\\", line 34, in lambda_handler\\n    send = recieve.replace(\\\"scatter\\\", \\\"gather\\\")\\n\"]}. Output:\n[INFO]\t2022-01-08T20:09:44.554Z\tb976dc9e-78e4-1a55-fde0-39f430240a37\tevent: {}\n[ERROR] AttributeError: 'dict' object has no attribute 'replace'\nTraceback (most recent call last):\n\u00a0\u00a0File \"/var/task/lambda.py\", line 34, in lambda_handler\n\u00a0\u00a0\u00a0\u00a0send = recieve.replace(\"scatter\", \"gather\")","errorType":"InvocationException","stackTrace":["  File \"/opt/code/localstack/localstack/services/awslambda/lambda_api.py\", line 794, in run_lambda\n    result = LAMBDA_EXECUTOR.execute(\n","  File \"/opt/code/localstack/localstack/services/awslambda/lambda_executors.py\", line 445, in execute\n    return do_execute()\n","  File \"/opt/code/localstack/localstack/services/awslambda/lambda_executors.py\", line 435, in do_execute\n    return _run(func_arn=func_arn)\n","  File \"/opt/code/localstack/localstack/utils/cloudwatch/cloudwatch_util.py\", line 158, in wrapped\n    raise e\n","  File \"/opt/code/localstack/localstack/utils/cloudwatch/cloudwatch_util.py\", line 154, in wrapped\n    result = func(*args, **kwargs)\n","  File \"/opt/code/localstack/localstack/services/awslambda/lambda_executors.py\", line 422, in _run\n    raise e\n","  File \"/opt/code/localstack/localstack/services/awslambda/lambda_executors.py\", line 418, in _run\n    result = self._execute(lambda_function, inv_context)\n","  File \"/opt/code/localstack/localstack/services/awslambda/lambda_executors.py\", line 871, in _execute\n    return super(LambdaExecutorReuseContainers, self)._execute(func_arn, *args, **kwargs)\n","  File \"/opt/code/localstack/localstack/services/awslambda/lambda_executors.py\", line 727, in _execute\n    result = self.run_lambda_executor(lambda_function=lambda_function, inv_context=inv_context)\n","  File \"/opt/code/localstack/localstack/services/awslambda/lambda_executors.py\", line 650, in run_lambda_executor\n    raise InvocationException(\n"]}
