{"errorMessage":"Lambda process returned with error. Result: {\"errorType\":\"NoSuchBucket\",\"errorMessage\":\"An error occurred (NoSuchBucket) when calling the GetObject operation: The specified bucket does not exist\",\"stackTrace\":[\"  File \\\"/var/task/lambda.py\\\", line 30, in lambda_handler\\n    resp = s3_client.get_object(Bucket=bucket, Key=recieve)\\n\",\"  File \\\"/var/task/botocore/client.py\\\", line 391, in _api_call\\n    return self._make_api_call(operation_name, kwargs)\\n\",\"  File \\\"/var/task/botocore/client.py\\\", line 719, in _make_api_call\\n    raise error_class(parsed_response, operation_name)\\n\"]}. Output:\n[ERROR] NoSuchBucket: An error occurred (NoSuchBucket) when calling the GetObject operation: The specified bucket does not exist\nTraceback (most recent call last):\n\u00a0\u00a0File \"/var/task/lambda.py\", line 30, in lambda_handler\n\u00a0\u00a0\u00a0\u00a0resp = s3_client.get_object(Bucket=bucket, Key=recieve)\n\u00a0\u00a0File \"/var/task/botocore/client.py\", line 391, in _api_call\n\u00a0\u00a0\u00a0\u00a0return self._make_api_call(operation_name, kwargs)\n\u00a0\u00a0File \"/var/task/botocore/client.py\", line 719, in _make_api_call\n\u00a0\u00a0\u00a0\u00a0raise error_class(parsed_response, operation_name)","errorType":"InvocationException","stackTrace":["  File \"/opt/code/localstack/localstack/services/awslambda/lambda_api.py\", line 794, in run_lambda\n    result = LAMBDA_EXECUTOR.execute(\n","  File \"/opt/code/localstack/localstack/services/awslambda/lambda_executors.py\", line 445, in execute\n    return do_execute()\n","  File \"/opt/code/localstack/localstack/services/awslambda/lambda_executors.py\", line 435, in do_execute\n    return _run(func_arn=func_arn)\n","  File \"/opt/code/localstack/localstack/utils/cloudwatch/cloudwatch_util.py\", line 158, in wrapped\n    raise e\n","  File \"/opt/code/localstack/localstack/utils/cloudwatch/cloudwatch_util.py\", line 154, in wrapped\n    result = func(*args, **kwargs)\n","  File \"/opt/code/localstack/localstack/services/awslambda/lambda_executors.py\", line 422, in _run\n    raise e\n","  File \"/opt/code/localstack/localstack/services/awslambda/lambda_executors.py\", line 418, in _run\n    result = self._execute(lambda_function, inv_context)\n","  File \"/opt/code/localstack/localstack/services/awslambda/lambda_executors.py\", line 871, in _execute\n    return super(LambdaExecutorReuseContainers, self)._execute(func_arn, *args, **kwargs)\n","  File \"/opt/code/localstack/localstack/services/awslambda/lambda_executors.py\", line 727, in _execute\n    result = self.run_lambda_executor(lambda_function=lambda_function, inv_context=inv_context)\n","  File \"/opt/code/localstack/localstack/services/awslambda/lambda_executors.py\", line 650, in run_lambda_executor\n    raise InvocationException(\n"]}
